Workbook

Sheet FL Spill Analysis
A1: trkg_num | B1: Operator Name | C1: operator_num | D1: incident_date | E1: facility_type | F1: Spill_Desc | G1: county | H1: Spill Type | I1: Root Cause | J1: Preventative Measure | K1: Root Cause Type | L1: Detailed Root Cause Type | M1: Long | N1: Lat | O1: oil_spilled | P1: oil_recovered | Q1: cond_spilled | R1: cond_recovered | S1: PW_spilled | T1: PW_recovered | U1: drilling_spilled | V1: drilling_recovered | W1: frac_spilled | X1: frac_recovered | Y1: other_spilled | Z1: other_recovered | AA1: other_spilled_specify | AB1: facility_status | AC1: Basin | AD1: Gathering? | AE1: Metallic? | AF1: =VLOOKUP(A1,#REF!, 7, FALSE) -> #REF! | AG1: =VLOOKUP(A1,#REF!, 8, FALSE) -> #REF! | AH1: On Location? | AI1: Fac or Loc ID
A2: 400768997 | B2: PETRON DEVELOPMENT COMPANY | C2: 69760 | D2: 42005 | E2: WELL | F2: A backup restraint that keeps our drive head on our PC pumps from twisting broke. This allowed the drive head to partially rotate. That caused a crack in a 3 x 2 sedge in the flow line. Steam was seen jetting from the crack (-20 degree temps vs. 110 degree water). We immediately shut the well in and made repairs. Weather conditions this coming Monday (Jan. 5th) should allow us a better look at the ground situation. However, we are confident we have the situation resolved. The ground is frozen and any water produced from the break has evaporated. The well remains shut-in until we can determine the exact sequence that caused the failure. | G2: WASHINGTON | I2: A backup restraint that keeps our drive head on our PC pumps from twisting broke. This allowed the drive head to partially rotate. That caused a crack in a 3 x 2 sedge in the flow line. Steam was seen jetting from the crack (-20 degree temps vs. 110 degree water). We immediately shut the well in and made repairs. | J2: We replaced the restraining chain with a heavier chain. | K2: Incorrect Operation | L2: Improper Procedures | M2: -102.84418 | N2: 40.14439 | O2: 1 | Q2: 0 | S2: 40 | U2: 0 | W2: 0 | Y2: NULL | AA2: NULL | AC2: DENVER JULESBURG BASIN | AD2: =IF(OR(IFERROR(SEARCH("gathering",F2)>0,FALSE),IFERROR(SEARCH("gathering",I2)>0,FALSE)),"Gathering","Non-Gathering") -> Non-Gathering | AE2: Unknown | AF2: =VLOOKUP(A2,#REF!, 7, FALSE) -> #REF! | AG2: =VLOOKUP(A2,#REF!, 8, FALSE) -> #REF! | AI2: =VLOOKUP(A2,#REF!,40,FALSE) -> #REF!
A3: 400763041 | B3: PIONEER NATURAL RESOURCES USA INC | C3: 10084 | D3: 42006 | E3: WATER GATHERING SYSTEM/LINE | F3: One inch valve on the waterline inside the meter house froze and broke, allowing approximately 20 bbls of produced water to spill out. Some water ran into the sediment trap and stopped there. Water also ran down the lease road into a sediment trap then into a bar ditch along the main road where it stopped. The well was shut off upon discovery so that repairs can be done. | G3: LAS ANIMAS | I3: One inch valve on the waterline inside the meter house froze and broke, allowing approximately 20 bbls of produced water to spill out. Some water ran into the sediment trap and stopped there. Water also ran down the lease road into a sediment trap then into a bar ditch along the main road where it stopped. The well was shut off upon discovery so that repairs can be done. | J3: The valve has been replaced and everything is operating normally. | K3: Natural Force Damage | L3: Valve Freeze | M3: -104.90956 | N3: 37.19037 | O3: 0 | Q3: 0 | S3: 20 | U3: 0 | W3: 0 | Y3: NULL | AA3: NULL | AC3: RATON BASIN | AD3: =IF(OR(IFERROR(SEARCH("gathering",F3)>0,FALSE),IFERROR(SEARCH("gathering",I3)>0,FALSE)),"Gathering","Non-Gathering") -> Non-Gathering | AE3: Unknown | AF3: =VLOOKUP(A3,#REF!, 7, FALSE) -> #REF! | AG3: =VLOOKUP(A3,#REF!, 8, FALSE) -> #REF! | AI3: =VLOOKUP(A3,#REF!,40,FALSE) -> #REF!
A4: 400763258 | B4: DCP MIDSTREAM LP | C4: 4680 | D4: 42006 | E4: PIPELINE | F4: The release occurred as a result of a trenching machine's trenching wheel coming into contact with a below ground flow line. When the trenching wheel came in contact with the flow line, approximately 3 barrels of condensate was released into the soil subsurface trenched excavation areal. The flow line was shut in and a vac truck immediately mobilized to the location and removed approximately 2 barrels from the trenched area. At this time it appears that the majority of the release was contained in the trench and there has been no impacts to groundwater. Continued remediation activities are being scheduled to take place as soon as possible. | G4: WELD | I4: A ditcher struck an active DCP line when digging a trench for a new pipeline to be set for another company. | J4: More accurate line locates and more frequent flagging to ensure it is highly visible where the pipeline is. | K4: Excavation Force Damage | L4: Line Strike | M4: -104.71265 | N4: 40.539301 | O4: 0 | Q4: 3 | S4: 0 | U4: 0 | W4: 0 | Y4: NULL | AA4: NULL | AC4: =VLOOKUP(A4,'Basin Blanks Report'!$B$1:$F$222,3,FALSE) -> DENVER JULESBURG BASIN | AD4: =IF(OR(IFERROR(SEARCH("gathering",F4)>0,FALSE),IFERROR(SEARCH("gathering",I4)>0,FALSE)),"Gathering","Non-Gathering") -> Non-Gathering | AE4: Unknown | AF4: =VLOOKUP(A4,#REF!, 7, FALSE) -> #REF! | AG4: =VLOOKUP(A4,#REF!, 8, FALSE) -> #REF! | AI4: =VLOOKUP(A4,#REF!,40,FALSE) -> #REF!
A5: 400764687 | B5: BARRETT CORPORATION* BILL | C5: 10071 | D5: 42008 | E5: TANK BATTERY | F5: Incident still under investigation, however, preliminary investigation has indicated that the burner on the heater treater blew out and dump line froze. Oil backed up into a vapor recovery tower and a pressure relief valve on the top of the tower was actuated. Between 1 and 3 bbls of oil was released out of the top of the tower in a fine mist that covered and area approximately 125 yards long by 50 yards wide. | G5: WELD | I5: Investigation has indicated that the burner on the heater treater blew out and dump line froze. Oil backed up into a vapor recovery tower and a pressure relief valve on the top of the tower was actuated. | J5: Ensure all heaters are adequately shrouded and/or oriented to minimize the change that the burner will be blown out by high winds. | K5: Incorrect Operation | L5: Improper Procedures | M5: -104.24814 | N5: 40.46566 | O5: 2 | Q5: 0 | S5: 0 | U5: 0 | W5: 0 | Y5: NULL | AA5: NULL | AC5: =VLOOKUP(A5,'Basin Blanks Report'!$B$1:$F$222,3,FALSE) -> DENVER JULESBURG BASIN | AD5: =IF(OR(IFERROR(SEARCH("gathering",F5)>0,FALSE),IFERROR(SEARCH("gathering",I5)>0,FALSE)),"Gathering","Non-Gathering") -> Non-Gathering | AE5: Unknown | AF5: =VLOOKUP(A5,#REF!, 7, FALSE) -> #REF! | AG5: =VLOOKUP(A5,#REF!, 8, FALSE) -> #REF! | AI5: =VLOOKUP(A5,#REF!,40,FALSE) -> #REF!
A6: 400764760 | B6: PIONEER NATURAL RESOURCES USA INC | C6: 10084 | D6: 42008 | E6: WELL | F6: PC well head torqued up and broke 2" line at flow tee.The well kept pumping and pumped aproximately 2000 bbls of produced water on location, and off NE side location. Water ran NE off the pad into a dry tributary of Chimney Canyon. Water was seen flowing into the dry Chimney Canyon confluence from the P&A’d Lorencito 3-19-34-66 location, but water was not seeing flowing into Lorencito Canyon lower down Chimney Canyon at the county road crossing. | G6: LAS ANIMAS | I6: PC well head torqued up for an unknown reason and broke 2" line at flow tee. The well kept pumping and pumped aproximately 2000 bbls of produced water spilled out. | J6: The old corroded 2" pipe at the wellhead has been replaced and the well is back to operating normally and the water going to surface discharge at Outfall 076 end of pipe. | K6: Corrosion | L6: Corrosion Type Unknown | M6: -104.83202 | N6: 37.07617 | O6: 0 | Q6: 0 | S6: 2000 | U6: 0 | W6: 0 | Y6: NULL | AA6: NULL | AC6: RATON BASIN | AD6: =IF(OR(IFERROR(SEARCH("gathering",F6)>0,FALSE),IFERROR(SEARCH("gathering",I6)>0,FALSE)),"Gathering","Non-Gathering") -> Non-Gathering | AE6: Metallic | AF6: =VLOOKUP(A6,#REF!, 7, FALSE) -> #REF! | AG6: =VLOOKUP(A6,#REF!, 8, FALSE) -> #REF! | AI6: =VLOOKUP(A6,#REF!,40,FALSE) -> #REF!
A7: 400765914 | B7: XTO ENERGY INC | C7: 100264 | D7: 42009 | E7: WATER GATHERING SYSTEM/LINE | F7: Isolation valve ruptured due to freeze. Line was isolated and all contributing wells were shut in. No water was recoved. | G7: LAS ANIMAS | I7: A block valve on a dischargeable water line froze, resulting in a release of dischargeable water. | J7: It is procedure to make sure all discharge points are open and free from freeze during winter months. | K7: Natural Force Damage | L7: Valve Freeze | M7: -104.91933 | N7: 37.13948 | O7: 0 | Q7: 0 | S7: 509 | U7: 0 | W7: 0 | Y7: NULL | AA7: NULL | AC7: RATON BASIN | AD7: =IF(OR(IFERROR(SEARCH("gathering",F7)>0,FALSE),IFERROR(SEARCH("gathering",I7)>0,FALSE)),"Gathering","Non-Gathering") -> Non-Gathering | AE7: Unknown | AF7: =VLOOKUP(A7,#REF!, 7, FALSE) -> #REF! | AG7: =VLOOKUP(A7,#REF!, 8, FALSE) -> #REF! | AI7: =VLOOKUP(A7,#REF!,40,FALSE) -> #REF!
A8: 400765386 | B8: OMIMEX PETROLEUM INC | C8: 66190 | D8: 42010 | E8: FLOWLINE | F8: Flowline rupture at a gas well. Well shut-in. We used a vac truck to remove production water. Frozen production water was placed in open swab tank. Once frozen production water thaws. The water will be transported to our SWD well. | G8: YUMA | I8: #N/A | J8: #N/A | K8: Unknown | L8: Unknown | M8: -102.32982 | N8: 40.43495 | O8: NULL | Q8: NULL | S8: NULL | U8: NULL | W8: NULL | Y8: NULL | AA8: NULL | AC8: =VLOOKUP(A8,'Basin Blanks Report'!$B$1:$F$222,3,FALSE) -> DENVER JULESBURG BASIN | AD8: =IF(OR(IFERROR(SEARCH("gathering",F8)>0,FALSE),IFERROR(SEARCH("gathering",I8)>0,FALSE)),"Gathering","Non-Gathering") -> Non-Gathering | AE8: Unknown | AF8: =VLOOKUP(A8,#REF!, 7, FALSE) -> #REF! | AG8: =VLOOKUP(A8,#REF!, 8, FALSE) -> #REF! | AI8: =VLOOKUP(A8,#REF!,40,FALSE) -> #REF!
A9: 400767943 | B9: CHEVRON USA INC | C9: 16700 | D9: 42012 | E9: FLOWLINE | F9: Thursday (01-08-2015) at approximately 2:47 PM a leak occurred on an on a 3" coated steel injection line at AC McLaughlin 23. Approximately 50.4BBLs of produced water was released. The lateral valve was shut in immediately upon detection. Vacuum truck recovered an estimated 40 BBLs. The affected has been water washed and soil samples will be taken. | G9: RIO BLANCO | I9: #N/A | J9: #N/A | K9: Unknown | L9: Unknown | M9: -108.9306 | N9: 40.1265 | O9: 0 | Q9: 0 | S9: 50.4 | U9: 0 | W9: 0 | Y9: 0 | AA9: 0 | AC9: PICEANCE BASIN | AD9: =IF(OR(IFERROR(SEARCH("gathering",F9)>0,FALSE),IFERROR(SEARCH("gathering",I9)>0,FALSE)),"Gathering","Non-Gathering") -> Non-Gathering | AE9: Metallic | AF9: =VLOOKUP(A9,#REF!, 7, FALSE) -> #REF! | AG9: =VLOOKUP(A9,#REF!, 8, FALSE) -> #REF! | AI9: =VLOOKUP(A9,#REF!,40,FALSE) -> #REF!
A10: 400768543 | B10: PIONEER NATURAL RESOURCES USA INC | C10: 10084 | D10: 42014 | E10: WELL | F10: Lease Operator found 2" ball vale on water line open, water ran off location down to the county road. It did not reach waters of the State. Incident is still under investigation. | G10: LAS ANIMAS | I10: Lack of communication among Lease Operators before time off. | J10: Valve has been closed and Lease Operators spoken to about communicating better. | K10: Incorrect Operation | L10: Valve Misalignment | M10: -104.91558 | N10: 37.25979 | O10: 0 | Q10: 0 | S10: 20 | U10: 0 | W10: 0 | Y10: NULL | AA10: NULL | AC10: RATON BASIN | AD10: =IF(OR(IFERROR(SEARCH("gathering",F10)>0,FALSE),IFERROR(SEARCH("gathering",I10)>0,FALSE)),"Gathering","Non-Gathering") -> Non-Gathering | AE10: Unknown | AF10: =VLOOKUP(A10,#REF!, 7, FALSE) -> #REF! | AG10: =VLOOKUP(A10,#REF!, 8, FALSE) -> #REF! | AI10: =VLOOKUP(A10,#REF!,40,FALSE) -> #REF!
A11: 400769226 | B11: CHEVRON USA INC | C11: 16700 | D11: 42014 | E11: FLOWLINE | F11: Saturday, (01-10-2015) at approximately 8:25 AM a produced water leak occurred on the lateral injection line to FV Larson 20. Approximately 100.8 BBLs of produced water was released. The wells and lateral valve was shut in immediately upon detection. Vacuum truck recovered an estimated 75 BBLs. The affected will be water washed and soil samples will be taken. | G11: RIO BLANCO | I11: #N/A | J11: #N/A | K11: Unknown | L11: Unknown | M11: -108.7936 | N11: 40.1039 | O11: 0 | Q11: 0 | S11: 100.8 | U11: 0 | W11: 0 | Y11: 0 | AA11: 0 | AC11: PICEANCE BASIN | AD11: =IF(OR(IFERROR(SEARCH("gathering",F11)>0,FALSE),IFERROR(SEARCH("gathering",I11)>0,FALSE)),"Gathering","Non-Gathering") -> Non-Gathering | AE11: Unknown | AF11: =VLOOKUP(A11,#REF!, 7, FALSE) -> #REF! | AG11: =VLOOKUP(A11,#REF!, 8, FALSE) -> #REF! | AI11: =VLOOKUP(A11,#REF!,40,FALSE) -> #REF!
A12: 400771524 | B12: NOBLE ENERGY INC | C12: 100322 | D12: 42018 | E12: FLOWLINE | F12: A pressure test was conducted on the flowline associated with the Victor C 29-10 well. Results indicated a loss of pressure and a leak. The area was uncovered and impacted soil above COGCC Table 910-1 standards was discovered. An excavation will be scheduled and the production equipment will remain shut in. | G12: WELD | I12: The flowline developed a leak | J12: the flowline will be repaired | K12: Unknown | L12: Unknown | M12: -104.57502 | N12: 40.279715 | O12: 0 | Q12: NULL | S12: NULL | U12: 0 | W12: 0 | Y12: NULL | AA12: NULL | AC12: =VLOOKUP(A12,'Basin Blanks Report'!$B$1:$F$222,3,FALSE) -> DENVER JULESBURG BASIN | AD12: =IF(OR(IFERROR(SEARCH("gathering",F12)>0,FALSE),IFERROR(SEARCH("gathering",I12)>0,FALSE)),"Gathering","Non-Gathering") -> Non-Gathering | AE12: Unknown | AF12: =VLOOKUP(A12,#REF!, 7, FALSE) -> #REF! | AG12: =VLOOKUP(A12,#REF!, 8, FALSE) -> #REF! | AI12: =VLOOKUP(A12,#REF!,40,FALSE) -> #REF!
A13: 400774763 | B13: OMIMEX PETROLEUM INC | C13: 66190 | D13: 42023 | E13: FLOWLINE | F13: The spill was discovered in the morning at the surface next to the meter shed. The well was shut in immediately. There was no standing water to be recovered. Water was seeped into the sand. The area of the flow line was excavated and flow line was repaired. | G13: YUMA | I13: #N/A | J13: #N/A | K13: Unknown | L13: Unknown | M13: -102.40858 | N13: 40.42344 | O13: NULL | Q13: NULL | S13: NULL | U13: NULL | W13: NULL | Y13: NULL | AA13: NULL | AC13: =VLOOKUP(A13,'Basin Blanks Report'!$B$1:$F$222,3,FALSE) -> DENVER JULESBURG BASIN | AD13: =IF(OR(IFERROR(SEARCH("gathering",F13)>0,FALSE),IFERROR(SEARCH("gathering",I13)>0,FALSE)),"Gathering","Non-Gathering") -> Non-Gathering | AE13: Unknown | AF13: =VLOOKUP(A13,#REF!, 7, FALSE) -> #REF! | AG13: =VLOOKUP(A13,#REF!, 8, FALSE) -> #REF! | AI13: =VLOOKUP(A13,#REF!,40,FALSE) -> #REF!
A14: 400775787 | B14: FOUNDATION ENERGY MANAGEMENT LLC | C14: 10112 | D14: 42023 | E14: FLOWLINE | F14: A broken valve can was discovered on the Davis Canyon pipeline, approximately 15 barrels of water was released from the line and ran about 60' down the road in front of the Columbine Springs 13C-14 location. The pumper shut-in the wells to the pipeline and constructed an earthen berm to contain the release. A vac truck was dispatched on 1/20 to vac up the fluid on the surface. | G14: RIO BLANCO | I14: #N/A | J14: #N/A | K14: Unknown | L14: Unknown | M14: -109.04637 | N14: 39.716919 | O14: 0 | Q14: 0 | S14: 15 | U14: 0 | W14: 0 | Y14: 0 | AA14: 0 | AC14: DOUGLAS CREEK ARCH | AD14: =IF(OR(IFERROR(SEARCH("gathering",F14)>0,FALSE),IFERROR(SEARCH("gathering",I14)>0,FALSE)),"Gathering","Non-Gathering") -> Non-Gathering | AE14: Unknown | AF14: =VLOOKUP(A14,#REF!, 7, FALSE) -> #REF! | AG14: =VLOOKUP(A14,#REF!, 8, FALSE) -> #REF! | AI14: =VLOOKUP(A14,#REF!,40,FALSE) -> #REF!
A15: 400777174 | B15: PIONEER NATURAL RESOURCES USA INC | C15: 10084 | D15: 42024 | E15: WATER GATHERING SYSTEM/LINE | F15: A PVC blade hit a buried water line along the edge of the road just west of the Marquez 41-32 location yesterday. A lease operator was in the area and was able to isolate the spill quickly. Approximately 1 bbl of produced water spilled out and ran east along the roadside for 75' before coming to a stop. The line has already been repaired and is back to operating normally. | G15: LAS ANIMAS | I15: A PVC blade hit a buried water line along the edge of the road | J15: The water line has been repaired and is back to operting normally. | K15: Other Outside Force Damage | L15: Line Strike | M15: -104.69052 | N15: 37.13448 | O15: 0 | Q15: 0 | S15: 1 | U15: 0 | W15: 0 | Y15: NULL | AA15: NULL | AC15: RATON BASIN | AD15: =IF(OR(IFERROR(SEARCH("gathering",F15)>0,FALSE),IFERROR(SEARCH("gathering",I15)>0,FALSE)),"Gathering","Non-Gathering") -> Non-Gathering | AE15: Unknown | AF15: =VLOOKUP(A15,#REF!, 7, FALSE) -> #REF! | AG15: =VLOOKUP(A15,#REF!, 8, FALSE) -> #REF! | AI15: =VLOOKUP(A15,#REF!,40,FALSE) -> #REF!
A16: 400778816 | B16: CRIMSON EXPLORATION OPERATING INC | C16: 10170 | D16: 42026 | E16: TANK BATTERY | F16: While conducting shallow excavation inside the tank battery berm to address a surface release (Document #s 400773673, 400777854), historical petroleum hydrocarbon impacts were encountered at approximately 6 inches below ground surface. There was no indication that any lines, tanks, or valves were leaking. All associated fittings were tight. The volume of the release is unknown. A topographic Site Location Map is provided as Figure 1. | G16: ELBERT | H16: x | I16: While conducting shallow excavation inside the tank battery berm to address a surface release (Document #s 400773673, 400777854), historical petroleum hydrocarbon impacts were encountered at approximately 6 inches below ground surface. There was no indication that any lines, tanks or valves were leaking. All associated fittings were tight. The volume of the release is unknown. | J16: The facility will be rebuilt with new piping. | K16: Unknown | L16: Unknown | M16: -104.57469 | N16: 39.51391 | O16: NULL | Q16: NULL | S16: NULL | U16: 0 | W16: 0 | Y16: NULL | AA16: NULL | AC16: DENVER JULESBURG BASIN | AD16: =IF(OR(IFERROR(SEARCH("gathering",F16)>0,FALSE),IFERROR(SEARCH("gathering",I16)>0,FALSE)),"Gathering","Non-Gathering") -> Non-Gathering | AE16: Unknown | AF16: =VLOOKUP(A16,#REF!, 7, FALSE) -> #REF! | AG16: =VLOOKUP(A16,#REF!, 8, FALSE) -> #REF! | AI16: =VLOOKUP(A16,#REF!,40,FALSE) -> #REF!
A17: 400779475 | B17: WARD PETROLEUM CORPORATION | C17: 10359 | D17: 42027 | E17: FLOWLINE | F17: Pumper noticed well had not produced for past two days, but polish rod was not hot. Walked around area and noticed spill on surface due to split in flowline. Flowline was test 1 month ago. Immediately shut well in and ordered backhoe to build temporary berm to keep spill from navigating further. Estimated 15 bbl release from pumper. Theoretical release for last two days is 8 bbl of oil. Will assess location with BLM, COGCC, and forestry service to properly remediate spill. | G17: WELD | I17: It is believed that during a routine hot oiling of the production flow line to clear it of paraffin that the hot oiler exceeded the specified maximum pressure of 80psi;This caused the flow line to split. Since the line was being cleared of paraffin, the corresponding pressure drop most likely looked like the paraffin had started moving towards the production battery, rather than leaking. | J17: Flow lines are tested yearly to determine their ability to operate. A replacement section will be added to the line and the line will be tested 80% above past tests to ensure function. | K17: Incorrect Operation | L17: Overpressure | M17: -104.521 | N17: 40.83795 | O17: 80 | Q17: 0 | S17: 0 | U17: 0 | W17: 0 | Y17: NULL | AA17: NULL | AC17: =VLOOKUP(A17,'Basin Blanks Report'!$B$1:$F$222,3,FALSE) -> DENVER JULESBURG BASIN | AD17: =IF(OR(IFERROR(SEARCH("gathering",F17)>0,FALSE),IFERROR(SEARCH("gathering",I17)>0,FALSE)),"Gathering","Non-Gathering") -> Non-Gathering | AE17: Unknown | AF17: =VLOOKUP(A17,#REF!, 7, FALSE) -> #REF! | AG17: =VLOOKUP(A17,#REF!, 8, FALSE) -> #REF! | AI17: =VLOOKUP(A17,#REF!,40,FALSE) -> #REF!
A18: 400779819 | B18: AUGUSTUS ENERGY RESOURCES LLC | C18: 10489 | D18: 42027 | E18: WELL | F18: The water line at the surface riser froze and created a small split near the Well head. Estimated between 10 & 20 bbls. No surface water to recover. Water line valve was shut off and broken pipe was replaced with a new piece of pipe. Soil samples have been taken and sent to lab for analysis and treatment will be determined on out come of analyses. The size of the line leak wsa approximately 18" and 96' long. See attached hand drawn map for details. 3 Soil samples were taken, 1 at wellhead, one east of wellhead lat 40.07738/Lon -102.54639 and one at end of affected area by lease road lat 40.07732/Lat -102.54605. | G18: YUMA | I18: #N/A | J18: #N/A | K18: Natural Force Damage | L18: Line Freeze | M18: -102.54659 | N18: 40.077328 | O18: 0 | Q18: 0 | S18: 20 | U18: 0 | W18: 0 | Y18: 0 | AA18: 0 | AC18: =VLOOKUP(A18,'Basin Blanks Report'!$B$1:$F$222,3,FALSE) -> DENVER JULESBURG BASIN | AD18: =IF(OR(IFERROR(SEARCH("gathering",F18)>0,FALSE),IFERROR(SEARCH("gathering",I18)>0,FALSE)),"Gathering","Non-Gathering") -> Non-Gathering | AE18: Unknown | AF18: =VLOOKUP(A18,#REF!, 7, FALSE) -> #REF! | AG18: =VLOOKUP(A18,#REF!, 8, FALSE) -> #REF! | AI18: =VLOOKUP(A18,#REF!,40,FALSE) -> #REF!
A19: 400781565 | B19: BAYSWATER EXPLORATION AND PRODUCTION LLC | C19: 10261 | D19: 42030 | E19: FLOWLINE | F19: A produced water release was found this morning on our Kaiser 17, 41, & 42-10 tank battery. The leak was in the dumpline in between the separator and the produced water tank. We estimate, at the most, one barrel of produced water was released. We are vacc’ing out the water from about a 26 inch diameter pot hole today. Once the water is removed, we will clean the soil and take soil samples for submittal. The pipeline will be replaced with a new pipe today or tomorrow. | G19: WELD | I19: A leak in a flowline | J19: This leaking flowline has been replaced and will no longer leak. | K19: Unknown | L19: Unknown | M19: -104.64019 | N19: 40.505964 | O19: 0 | Q19: 0 | S19: 1 | U19: 0 | W19: 0 | Y19: NULL | AA19: NULL | AC19: =VLOOKUP(A19,'Basin Blanks Report'!$B$1:$F$222,3,FALSE) -> DENVER JULESBURG BASIN | AD19: =IF(OR(IFERROR(SEARCH("gathering",F19)>0,FALSE),IFERROR(SEARCH("gathering",I19)>0,FALSE)),"Gathering","Non-Gathering") -> Non-Gathering | AE19: Unknown | AF19: =VLOOKUP(A19,#REF!, 7, FALSE) -> #REF! | AG19: =VLOOKUP(A19,#REF!, 8, FALSE) -> #REF! | AI19: =VLOOKUP(A19,#REF!,40,FALSE) -> #REF!
A20: 400782763 | B20: KERR MCGEE GATHERING LLC | C20: 47121 | D20: 42031 | E20: PIPELINE | F20: A release was discovered at the 38-0000-5569-6" pipeline when condensate was found surfacing above ground. The pipeline was immediately shut in and excavation activities commenced. Groundwater was encountered in the excavation area at approximately 20 feet below ground surface (bgs). A groundwater sample (GW01) was collected and submitted to Origins Laboratory in Denver, Colorado for analysis of benzene, toluene, ethylbenzene, and total xylenes (BTEX) by USEPA Method 8260B. Analytical results received on January 27, 2015 indicated benzene and total xylenes concentrations were in exceedance of applicable COGCC Table 910-1 groundwater standards. Groundwater analytical data is presented in the attached Table 1 and laboratory analytical report. Site investigation activities are on-going and will be summarized in a subsequent Supplemental Form 19. | G20: ADAMS | I20: Condensate was discovered surfacing on the ground above the buried pipeline. A corrosion hole in the line was discovered upon excavation activities. | J20: The production line was repaired and will be routinely tested for integrity. | K20: Corrosion | L20: Corrosion Type Unknown | M20: -104.5741 | N20: 39.9259 | O20: 0 | Q20: NULL | S20: 0 | U20: 0 | W20: 0 | Y20: NULL | AA20: NULL | AC20: DENVER JULESBURG BASIN | AD20: =IF(OR(IFERROR(SEARCH("gathering",F20)>0,FALSE),IFERROR(SEARCH("gathering",I20)>0,FALSE)),"Gathering","Non-Gathering") -> Non-Gathering | AE20: Metallic | AF20: =VLOOKUP(A20,#REF!, 7, FALSE) -> #REF! | AG20: =VLOOKUP(A20,#REF!, 8, FALSE) -> #REF! | AI20: =VLOOKUP(A20,#REF!,40,FALSE) -> #REF!
A21: 400783018 | B21: VANGUARD OPERATING LLC | C21: 10531 | D21: 42033 | E21: WELL PAD | F21: During routine maintenance activities, impacted soil was encountered on the eastern end of the tank battery. The visually impacted soil was encountered within the subsurface immediately around the dump line. A third-party consultant collected multiple samples from the excavation and these samples were sent for laboratory analysis. The excavated soils within the lined secondary containment were also sampled and analyzed. Laboratory results indicated that all four sidewall samples were compliant with Table 910-1 Concentration Levels except for the samples collected from the base of the excavation and from the spoils pile. Both of these samples exceeded the Concentration Levels for TPH. Excavation activities continued to identify the vertical extent of of the TPH impact and additional samples were collected. These analytical results are pending and additonal information will be provided in a supplemental submittal. | G21: GARFIELD | H21: x | I21: During routine maintenance activities, impacted soil was encountered at the eastern end of the tank battery. Visually impacted soil was encountered within the subsurface immediately around the dump line. Potential corrosion issues with the dump line are likely the cause of the historic impacts. The 2014 pressure test data for this facility has been included as an attachment at the direction of COGCC staff. | J21: All dump lines will be replaced as a precautionary measure and sacrificial anodes will be installed on all new lines to address any potential corrosion issues in the future. | K21: Corrosion | L21: Corrosion Type Unknown | M21: -107.58246 | N21: 39.483291 | O21: 0 | Q21: NULL | S21: NULL | U21: 0 | W21: 0 | Y21: NULL | AA21: NULL | AC21: PICEANCE BASIN | AD21: =IF(OR(IFERROR(SEARCH("gathering",F21)>0,FALSE),IFERROR(SEARCH("gathering",I21)>0,FALSE)),"Gathering","Non-Gathering") -> Non-Gathering | AE21: Metallic | AF21: =VLOOKUP(A21,#REF!, 7, FALSE) -> #REF! | AG21: =VLOOKUP(A21,#REF!, 8, FALSE) -> #REF! | AI21: =VLOOKUP(A21,#REF!,40,FALSE) -> #REF!
A22: 400784214 | B22: FOUNDATION ENERGY MANAGEMENT LLC | C22: 10112 | D22: 42033 | E22: FLOWLINE | F22: Turned well back to production after a flowline repair and remediation project East of the Sooner 13-16 wellpad. Pumper returned to location the next day to discover a new flowline leak that had released approximately 2 bbls of water. A vac truck was dispatched immediately to vac up the fluids on the surface and a crew will be digging down to the flowline to determine cause of leak, repair and remediate contaminated soil per COGCC regs. | G22: WELD | I22: Flowline leaked after initial repair and test. Working to repair and re-test before turning the well back online. | J22: Frequently testing our flowlines to ensure no leaks or corrosion. | K22: Unknown | L22: Unknown | M22: -103.87093 | N22: 40.65633 | O22: 0 | Q22: 0 | S22: 2 | U22: 0 | W22: 0 | Y22: NULL | AA22: NULL | AC22: =VLOOKUP(A22,'Basin Blanks Report'!$B$1:$F$222,3,FALSE) -> DENVER JULESBURG BASIN | AD22: =IF(OR(IFERROR(SEARCH("gathering",F22)>0,FALSE),IFERROR(SEARCH("gathering",I22)>0,FALSE)),"Gathering","Non-Gathering") -> Non-Gathering | AE22: Unknown | AF22: =VLOOKUP(A22,#REF!, 7, FALSE) -> #REF! | AG22: =VLOOKUP(A22,#REF!, 8, FALSE) -> #REF! | AI22: =VLOOKUP(A22,#REF!,40,FALSE) -> #REF!
A23: 400785370 | B23: DCP MIDSTREAM LP | C23: 4680 | D23: 42037 | E23: GAS GATHERING SYSTEM | F23: A release originating from an underground pipeline occured on the Tampa Compressor Station owned by DCP Midstream. The release has believed to have been stopped and soil remediation activities have begun. An investigation is underway as to what may have caused the initial release. More information will be provided on the 10 day follow-up report. | G23: WELD | I23: #N/A | J23: #N/A | K23: Unknown | L23: Unknown | M23: -104.48 | N23: 40.18 | O23: NULL | Q23: NULL | S23: 0 | U23: 0 | W23: 0 | Y23: NULL | AA23: NULL | AC23: =VLOOKUP(A23,'Basin Blanks Report'!$B$1:$F$222,3,FALSE) -> DENVER JULESBURG BASIN | AD23: =IF(OR(IFERROR(SEARCH("gathering",F23)>0,FALSE),IFERROR(SEARCH("gathering",I23)>0,FALSE)),"Gathering","Non-Gathering") -> Non-Gathering | AE23: Unknown | AF23: =VLOOKUP(A23,#REF!, 7, FALSE) -> #REF! | AG23: =VLOOKUP(A23,#REF!, 8, FALSE) -> #REF! | AI23: =VLOOKUP(A23,#REF!,40,FALSE) -> #REF!
A24: 400785554 | B24: DCP MIDSTREAM LP | C24: 4680 | D24: 42037 | E24: PIPELINE | F24: On February 2, 2015 DCP was notified about a potential underground pipeline release located 1/4 mile southwest of the intersection of CR 18 and CR 21. Upon investigation it was determined that DCP had a 2'' field gathering line that was leaking. The liquids in the line were removed via vacuum truck. Current repair activities and remediation plans are being scheduled. The leak has stopped and no impacts to groundwater have been identifed at this time. | G24: WELD | I24: #N/A | J24: #N/A | K24: Unknown | L24: Unknown | M24: -104.872 | N24: 40.113 | O24: NULL | Q24: NULL | S24: NULL | U24: NULL | W24: NULL | Y24: NULL | AA24: NULL | AC24: =VLOOKUP(A24,'Basin Blanks Report'!$B$1:$F$222,3,FALSE) -> DENVER JULESBURG BASIN | AD24: =IF(OR(IFERROR(SEARCH("gathering",F24)>0,FALSE),IFERROR(SEARCH("gathering",I24)>0,FALSE)),"Gathering","Non-Gathering") -> Gathering | AE24: Unknown | AF24: =VLOOKUP(A24,#REF!, 7, FALSE) -> #REF! | AG24: =VLOOKUP(A24,#REF!, 8, FALSE) -> #REF! | AI24: =VLOOKUP(A24,#REF!,40,FALSE) -> #REF!
A25: 400786064 | B25: K P KAUFFMAN COMPANY INC | C25: 46290 | D25: 42038 | E25: FLOWLINE | F25: This is to notify of a 3 bbl oil and water spill that was discovered yesterday, February 3, 2015. At about 16:00 Encana notified K.P. Kauffman Company, Inc. (KPK) of a leak in or near Encana's dry retention pond. The leak appears to come from a pipe that Encana cut while building the retention pond. It was caused by a valve failure isolating the consolidation line and the cut line. Since the spill took place within Encana's fenced area, KPK was denied access to start cleanup; however, immediately upon discovery of the spill, Encana started digging out the contaminated soil and determined the extent of the contamination with visual inspection. KPK has now been granted access to the location and will take over the remediation operations. Based on flowline volumes and well production, it is estimated that 3 bbl of oil and produced water were spilled. | G25: WELD | I25: The leak appears to come from a pipe that Encana cut while building the retention pond. It was caused by a valve failure isolating the consolidation line and the cut line. | J25: Following proper repairs to the damged flowline, the excavated area will be filled in with clean fill dirt. A new flow line outside the retention pond will be installed. | K25: Excavation Force Damage | L25: Line Strike | M25: -104.88918 | N25: 40.01888 | O25: 1 | Q25: 0 | S25: 1 | U25: 0 | W25: 0 | Y25: NULL | AA25: NULL | AC25: =VLOOKUP(A25,'Basin Blanks Report'!$B$1:$F$222,3,FALSE) -> DENVER JULESBURG BASIN | AD25: =IF(OR(IFERROR(SEARCH("gathering",F25)>0,FALSE),IFERROR(SEARCH("gathering",I25)>0,FALSE)),"Gathering","Non-Gathering") -> Non-Gathering | AE25: Unknown | AF25: =VLOOKUP(A25,#REF!, 7, FALSE) -> #REF! | AG25: =VLOOKUP(A25,#REF!, 8, FALSE) -> #REF! | AI25: =VLOOKUP(A25,#REF!,40,FALSE) -> #REF!
A26: 400786068 | B26: AUGUSTUS ENERGY RESOURCES LLC | C26: 10489 | D26: 42038 | E26: FLOWLINE | F26: the Poly pipe fuse broke, valves where shut to isolate the water, no surface water to recover, poly fuse was repaired. Size of area was approx 5' x 5'. Soil samples have been taken and will be submitted on a supplemental form 19 when received. As soon as analyses are received they will be reviewed and treated per the lab recommendations. The location will be strawed to help hold the moisture. | G26: YUMA | I26: #N/A | J26: #N/A | K26: Pipe, Weld, or Joint Failure | L26: Poly Fitting or Fuse Failure | M26: -102.407 | N26: 39.991201 | O26: 0 | Q26: 0 | S26: 15 | U26: 0 | W26: 0 | Y26: NULL | AA26: NULL | AC26: =VLOOKUP(A26,'Basin Blanks Report'!$B$1:$F$222,3,FALSE) -> DENVER JULESBURG BASIN | AD26: =IF(OR(IFERROR(SEARCH("gathering",F26)>0,FALSE),IFERROR(SEARCH("gathering",I26)>0,FALSE)),"Gathering","Non-Gathering") -> Non-Gathering | AE26: Non-Metallic | AF26: =VLOOKUP(A26,#REF!, 7, FALSE) -> #REF! | AG26: =VLOOKUP(A26,#REF!, 8, FALSE) -> #REF! | AI26: =VLOOKUP(A26,#REF!,40,FALSE) -> #REF!
A27: 400786811 | B27: GREAT WESTERN OPERATING COMPANY LLC | C27: 10110 | D27: 42038 | E27: TANK BATTERY | F27: 915 pm Tues 02.03.15 a leak from a subsurface poly collector line was identified. All wells had been shut in for well mitigations in the area so there was minimal pressure on the line. Approximately 2 bbls of produced water with a skim of hydrocarbons was removed from the hole created by the leak. Some liquid did migrate down the road and this was all picked up also. | G27: WELD | I27: Subsurface collector line rupture. | J27: Approximately 2 barrels of produced water were removed from the hole created by the leak and the ruptured collector line was repaired. | K27: Unknown | L27: Unknown | M27: -104.88052 | N27: 40.493953 | O27: 0 | Q27: 0 | S27: 2 | U27: 0 | W27: 0 | Y27: NULL | AA27: NULL | AC27: =VLOOKUP(A27,'Basin Blanks Report'!$B$1:$F$222,3,FALSE) -> DENVER JULESBURG BASIN | AD27: =IF(OR(IFERROR(SEARCH("gathering",F27)>0,FALSE),IFERROR(SEARCH("gathering",I27)>0,FALSE)),"Gathering","Non-Gathering") -> Non-Gathering | AE27: Non-Metallic | AF27: =VLOOKUP(A27,#REF!, 7, FALSE) -> #REF! | AG27: =VLOOKUP(A27,#REF!, 8, FALSE) -> #REF! | AI27: =VLOOKUP(A27,#REF!,40,FALSE) -> #REF!
A28: 400786818 | B28: KERR MCGEE OIL & GAS ONSHORE LP | C28: 47120 | D28: 42038 | E28: TANK BATTERY | F28: During deconstruction activities at the HSR-Charlene 2-36 tank battery, historical petroleum hydrocarbon impacts were encountered beneath the produced water sump. There was no indication that the dump lines or the produced water tank were leaking. The volume of the release is unknown. Confirmation soil and groundwater samples were collected from the excavation and the analytical results and excavation details are provided below. A topographic Site Location Map showing the general location of the release is attached as Figure 1. | G28: WELD | H28: x | I28: During deconstruction activities at the HSR-Charlene 2-36 tank battery, historical petroleum hydrocarbon impacts were encountered beneath the produced water sump. There was no indication that the dump lines or the produced water tank were leaking. The volume of the release is unknown. | J28: The tank battery was removed and the site was restored to it's pre-release grade. | K28: Unknown | L28: Unknown | M28: -104.83497 | N28: 40.182715 | O28: NULL | Q28: 0 | S28: NULL | U28: 0 | W28: 0 | Y28: NULL | AA28: NULL | AC28: =VLOOKUP(A28,'Basin Blanks Report'!$B$1:$F$222,3,FALSE) -> DENVER JULESBURG BASIN | AD28: =IF(OR(IFERROR(SEARCH("gathering",F28)>0,FALSE),IFERROR(SEARCH("gathering",I28)>0,FALSE)),"Gathering","Non-Gathering") -> Non-Gathering | AE28: Unknown | AF28: =VLOOKUP(A28,#REF!, 7, FALSE) -> #REF! | AG28: =VLOOKUP(A28,#REF!, 8, FALSE) -> #REF! | AI28: =VLOOKUP(A28,#REF!,40,FALSE) -> #REF!
A29: 400787201 | B29: PIONEER NATURAL RESOURCES USA INC | C29: 10084 | D29: 42038 | E29: WATER GATHERING SYSTEM/LINE | F29: Gas buster on the SE corner of location froze and broke, allowing approximately 10 bbls of produced water to pool on location. Some water ran south off location and skirted along the toe of the hillside until coming to a stop in an open grassy area. The spill was isolated upon discovery and repairs are being done to the gas buster and water line. | G29: LAS ANIMAS | I29: Gas buster on the SE corner of location froze and broke | J29: Gas buster and valve has been replaced and things are operating normally | K29: Natural Force Damage | L29: Valve Freeze | M29: -104.79961 | N29: 37.21143 | O29: 0 | Q29: 0 | S29: 10 | U29: 0 | W29: 0 | Y29: NULL | AA29: NULL | AC29: RATON BASIN | AD29: =IF(OR(IFERROR(SEARCH("gathering",F29)>0,FALSE),IFERROR(SEARCH("gathering",I29)>0,FALSE)),"Gathering","Non-Gathering") -> Non-Gathering | AE29: Unknown | AF29: =VLOOKUP(A29,#REF!, 7, FALSE) -> #REF! | AG29: =VLOOKUP(A29,#REF!, 8, FALSE) -> #REF! | AI29: =VLOOKUP(A29,#REF!,40,FALSE) -> #REF!
A30: 400787752 | B30: NOBLE ENERGY INC | C30: 100322 | D30: 42039 | E30: FLOWLINE | F30: The flow line was pressure tested and a leak was discovered 30 feet from the well head. All production equipment is shut in and an excavation is scheduled. | G30: WELD | I30: During a pressure test of the flowline a section lost pressure | J30: The flowline will be repaired or replaced. | K30: Unknown | L30: Unknown | M30: -104.5164 | N30: 40.27758 | O30: 0 | Q30: NULL | S30: NULL | U30: 0 | W30: 0 | Y30: NULL | AA30: NULL | AC30: =VLOOKUP(A30,'Basin Blanks Report'!$B$1:$F$222,3,FALSE) -> DENVER JULESBURG BASIN | AD30: =IF(OR(IFERROR(SEARCH("gathering",F30)>0,FALSE),IFERROR(SEARCH("gathering",I30)>0,FALSE)),"Gathering","Non-Gathering") -> Non-Gathering | AE30: Unknown | AF30: =VLOOKUP(A30,#REF!, 7, FALSE) -> #REF! | AG30: =VLOOKUP(A30,#REF!, 8, FALSE) -> #REF! | AI30: =VLOOKUP(A30,#REF!,40,FALSE) -> #REF!
A31: 400788049 | B31: AUGUSTUS ENERGY RESOURCES LLC | C31: 10489 | D31: 42041 | E31: WELL | F31: Poly pipe broke, we believe it was caused by freezing and thawing as there was approx. a 3" split in the pipe. We removed and replaced the broken piece. The valve was shut to isolate the water, there was no surface water to recover. Estimated bbls is 10-12. The approx. dimension of the affected area is 20' by 30', 2 spots were sampled as well as a background area and the samples have been submitted for testing. A supplemental form 19 will be submitted with soil analyses. | G31: YUMA | I31: #N/A | J31: #N/A | K31: Natural Force Damage | L31: Line Freeze | M31: -102.49659 | N31: 40.28889 | O31: 0 | Q31: 0 | S31: 12 | U31: 0 | W31: 0 | Y31: 0 | AA31: 0 | AC31: =VLOOKUP(A31,'Basin Blanks Report'!$B$1:$F$222,3,FALSE) -> DENVER JULESBURG BASIN | AD31: =IF(OR(IFERROR(SEARCH("gathering",F31)>0,FALSE),IFERROR(SEARCH("gathering",I31)>0,FALSE)),"Gathering","Non-Gathering") -> Non-Gathering | AE31: Non-Metallic | AF31: =VLOOKUP(A31,#REF!, 7, FALSE) -> #REF! | AG31: =VLOOKUP(A31,#REF!, 8, FALSE) -> #REF! | AI31: =VLOOKUP(A31,#REF!,40,FALSE) -> #REF!
A32: 400788096 | B32: AUGUSTUS ENERGY RESOURCES LLC | C32: 10489 | D32: 42041 | E32: WELL | F32: It appears the fuse in the poly pipe broke. The valves were shut to isolate the water. An Electra fuse was used to repair/replace the broken fuse. The size of the affected area is approx. 132' long and 12' wide. 2 Soil samples were taken from the affected area and 1 from the background. Soil Analyses will be submitted on a Supplemental form 19 and we will reclaim the area based on the recommendations supplied with the Analyses. | G32: YUMA | I32: #N/A | J32: #N/A | K32: Pipe, Weld, or Joint Failure | L32: Poly Fitting or Fuse Failure | M32: -102.27949 | N32: 39.93369 | O32: NULL | Q32: NULL | S32: NULL | U32: NULL | W32: NULL | Y32: NULL | AA32: NULL | AC32: DENVER JULESBURG BASIN | AD32: =IF(OR(IFERROR(SEARCH("gathering",F32)>0,FALSE),IFERROR(SEARCH("gathering",I32)>0,FALSE)),"Gathering","Non-Gathering") -> Non-Gathering | AE32: Non-Metallic | AF32: =VLOOKUP(A32,#REF!, 7, FALSE) -> #REF! | AG32: =VLOOKUP(A32,#REF!, 8, FALSE) -> #REF! | AI32: =VLOOKUP(A32,#REF!,40,FALSE) -> #REF!
A33: 400789484 | B33: CHEVRON USA INC | C33: 16700 | D33: 42044 | E33: FLOWLINE | F33: Monday (02-09-2015) at approximately 9:46 AM a produced water leak occurred on the lateral injection line to AC McLaughlin 93. Approximately 112.9 BBLs of produced water was released. The lateral valve was shut in immediately upon detection. Vacuum truck recovered an estimated 100 BBLs. The affected area has been water washed and soil samples will be taken. Water ran into a dry erosion channel. | G33: RIO BLANCO | I33: #N/A | J33: #N/A | K33: Unknown | L33: Unknown | M33: -108.9118 | N33: 40.1484 | O33: NULL | Q33: NULL | S33: 112.9 | U33: NULL | W33: NULL | Y33: NULL | AA33: NULL | AC33: PICEANCE BASIN | AD33: =IF(OR(IFERROR(SEARCH("gathering",F33)>0,FALSE),IFERROR(SEARCH("gathering",I33)>0,FALSE)),"Gathering","Non-Gathering") -> Non-Gathering | AE33: Unknown | AF33: =VLOOKUP(A33,#REF!, 7, FALSE) -> #REF! | AG33: =VLOOKUP(A33,#REF!, 8, FALSE) -> #REF! | AI33: =VLOOKUP(A33,#REF!,40,FALSE) -> #REF!
A34: 400790938 | B34: BAYSWATER EXPLORATION AND PRODUCTION LLC | C34: 10261 | D34: 42046 | E34: FLOWLINE | F34: Due to an inspection notice on the Causey 17 Wellhead indicating that stained soil existed and needed to be remediated, our foreman started the clean up and found a larger area of contamination. He believes that some of this contamination is historical, and some is recent from a probable flowline leak. He is currently investigating the cause of the leak and excavating the area to determine the extent of the contamination. | G34: ADAMS | I34: Leak in the flowline | J34: Older flowlines were removed. Current working flowline was vacc'ed out and pressure tested (see attached) Connectors were also replaced. | K34: Unknown | L34: Unknown | M34: -103.7466 | N34: 39.859699 | O34: 10 | Q34: 0 | S34: 200 | U34: 0 | W34: 0 | Y34: NULL | AA34: NULL | AC34: DENVER JULESBURG BASIN | AD34: =IF(OR(IFERROR(SEARCH("gathering",F34)>0,FALSE),IFERROR(SEARCH("gathering",I34)>0,FALSE)),"Gathering","Non-Gathering") -> Non-Gathering | AE34: Unknown | AF34: =VLOOKUP(A34,#REF!, 7, FALSE) -> #REF! | AG34: =VLOOKUP(A34,#REF!, 8, FALSE) -> #REF! | AI34: =VLOOKUP(A34,#REF!,40,FALSE) -> #REF!
A35: 400791362 | B35: PDC ENERGY INC | C35: 69175 | D35: 42046 | E35: TANK BATTERY | F35: While completing construction activities at the Maxey 2, 33, 43, 44-24, 24D facility, historical impacts were encountered in the area of a flowline. Based on field interpretations, it appears that groundwater impacts are present. Confirmation soil and groundwater samples will be collected. | G35: WELD | H35: x | I35: Historic impacts were discovered during construction activities. | J35: The flow line was replaced and will be routinely pressure tested. | K35: Unknown | L35: Unknown | M35: -104.605 | N35: 40.378526 | O35: NULL | Q35: 0 | S35: 0 | U35: 0 | W35: 0 | Y35: NULL | AA35: NULL | AC35: =VLOOKUP(A35,'Basin Blanks Report'!$B$1:$F$222,3,FALSE) -> DENVER JULESBURG BASIN | AD35: =IF(OR(IFERROR(SEARCH("gathering",F35)>0,FALSE),IFERROR(SEARCH("gathering",I35)>0,FALSE)),"Gathering","Non-Gathering") -> Non-Gathering | AE35: Unknown | AF35: =VLOOKUP(A35,#REF!, 7, FALSE) -> #REF! | AG35: =VLOOKUP(A35,#REF!, 8, FALSE) -> #REF! | AI35: =VLOOKUP(A35,#REF!,40,FALSE) -> #REF!
A36: 400792553 | B36: KERR MCGEE OIL & GAS ONSHORE LP | C36: 47120 | D36: 42047 | E36: TANK BATTERY | F36: A release was discovered below the dump lines during battery reconstruction activities at the Wierman 43-7 (1) production facility. Approximately 20 cubic yards of impacted material were removed and transported to the Buffalo Ridge Landfill in Keenesburg, Colorado for disposal. Groundwater was encountered in the excavation area at approximately 3.5 feet below ground surface (bgs). A groundwater sample (GW01) was collected and submitted to Origins Laboratory in Denver, Colorado for analysis of benzene, toluene, ethylbenzene, and total xylenes (BTEX) by USEPA Method 8260B. Analytical results received on February 13, 2015 indicated benzene concentrations were in exceedance of applicable COGCC Table 910-1 standards. Excavation activities are on-going at this location and will be summarized in a subsequent Supplemental Form 19. | G36: ADAMS | H36: x | I36: During the replacement of the tank battery, hydrocarbon impacts were discovered along the dump line. | J36: The battery will be rebuilt with a geosynthetic liner, a poly drain line, and a double walled fiberglass produced water tank. | K36: Unknown | L36: Unknown | M36: -104.92609 | N36: 39.975673 | O36: 0 | Q36: NULL | S36: NULL | U36: 0 | W36: 0 | Y36: NULL | AA36: NULL | AC36: DENVER JULESBURG BASIN | AD36: =IF(OR(IFERROR(SEARCH("gathering",F36)>0,FALSE),IFERROR(SEARCH("gathering",I36)>0,FALSE)),"Gathering","Non-Gathering") -> Non-Gathering | AE36: Unknown | AF36: =VLOOKUP(A36,#REF!, 7, FALSE) -> #REF! | AG36: =VLOOKUP(A36,#REF!, 8, FALSE) -> #REF! | AI36: =VLOOKUP(A36,#REF!,40,FALSE) -> #REF!
A37: 400792604 | B37: NOBLE ENERGY INC | C37: 100322 | D37: 42048 | E37: TANK BATTERY | F37: Pipe on water vault malfunctioned and 69 bbls of produced water was unintentionally released. Malfunction is currently under investigation. 7bbls were recovered while 62 bbls were released to ground surface. A 3rd party environmental consultant was called to assess the impacts outside of the berm area. Production equipment has been shut in. | G37: WELD | I37: The produced water line malfunctioned and will be repaired and tested prior to being put back into production. | J37: The produced water line will be repaired | K37: Unknown | L37: Unknown | M37: -104.51987 | N37: 40.341168 | O37: 0 | Q37: 0 | S37: 69 | U37: 0 | W37: 0 | Y37: NULL | AA37: NULL | AC37: =VLOOKUP(A37,'Basin Blanks Report'!$B$1:$F$222,3,FALSE) -> DENVER JULESBURG BASIN | AD37: =IF(OR(IFERROR(SEARCH("gathering",F37)>0,FALSE),IFERROR(SEARCH("gathering",I37)>0,FALSE)),"Gathering","Non-Gathering") -> Non-Gathering | AE37: Unknown | AF37: =VLOOKUP(A37,#REF!, 7, FALSE) -> #REF! | AG37: =VLOOKUP(A37,#REF!, 8, FALSE) -> #REF! | AI37: =VLOOKUP(A37,#REF!,40,FALSE) -> #REF!
A38: 400795311 | B38: NOBLE ENERGY INC | C38: 100322 | D38: 42053 | E38: TANK BATTERY | F38: The produced water line malfunctioned releasing 20 gallons of produced water to the groundsurface inside containment and an undetermined amount of produced water below groundsurface. All production equipment has been shut in and a hydroexcavator is on location uncovering the flow lines. Remediation options are being evaluated. Site Location: Sauer Econode F33 | G38: WELD | I38: The produced water line leading to the produced water vault from the separator developed a leak. The portion of the line will be cut and replaced. A pressure test will be conducted to ensure the repaired section holds pressure. | J38: The portinon of the line will be repaired. | K38: Unknown | L38: Unknown | M38: -104.67337 | N38: 40.351023 | O38: 0 | Q38: 0 | S38: NULL | U38: 0 | W38: 0 | Y38: NULL | AA38: NULL | AC38: =VLOOKUP(A38,'Basin Blanks Report'!$B$1:$F$222,3,FALSE) -> DENVER JULESBURG BASIN | AD38: =IF(OR(IFERROR(SEARCH("gathering",F38)>0,FALSE),IFERROR(SEARCH("gathering",I38)>0,FALSE)),"Gathering","Non-Gathering") -> Non-Gathering | AE38: Unknown | AF38: =VLOOKUP(A38,#REF!, 7, FALSE) -> #REF! | AG38: =VLOOKUP(A38,#REF!, 8, FALSE) -> #REF! | AI38: =VLOOKUP(A38,#REF!,40,FALSE) -> #REF!
A39: 400795533 | B39: AUGUSTUS ENERGY RESOURCES LLC | C39: 10489 | D39: 42053 | E39: FLOWLINE | F39: Bad Poly Fuse broke, isolation valves were shut. There was no surface water, but we did have a vac truck suck the water from the line. Poly fuse was repaired. Size of affected area was aprox. 38' long x 6' wide. Soil samples were taken and have been sent to lab for analysis. The area will be treated with Pelleted Grade gypsum, straw will be stitched to prevent erosion and depending on the soil analysis results will determine when area will be re-seeded. | G39: YUMA | I39: #N/A | J39: #N/A | K39: Pipe, Weld, or Joint Failure | L39: Poly Fitting or Fuse Failure | M39: -102.47744 | N39: 40.00284 | O39: NULL | Q39: NULL | S39: NULL | U39: NULL | W39: NULL | Y39: NULL | AA39: NULL | AC39: =VLOOKUP(A39,'Basin Blanks Report'!$B$1:$F$222,3,FALSE) -> DENVER JULESBURG BASIN | AD39: =IF(OR(IFERROR(SEARCH("gathering",F39)>0,FALSE),IFERROR(SEARCH("gathering",I39)>0,FALSE)),"Gathering","Non-Gathering") -> Non-Gathering | AE39: Non-Metallic | AF39: =VLOOKUP(A39,#REF!, 7, FALSE) -> #REF! | AG39: =VLOOKUP(A39,#REF!, 8, FALSE) -> #REF! | AI39: =VLOOKUP(A39,#REF!,40,FALSE) -> #REF!
A40: 400802279 | B40: PIONEER NATURAL RESOURCES USA INC | C40: 10084 | D40: 42064 | E40: WATER GATHERING SYSTEM/LINE | F40: Above ground water gathering line had a small split in it next to the meter house. Approximately 1 bbl of produced water sprayed out on location and melted snow in the spray area. No water left location. The well was shut off upon discovery and will be restarted after repairs to the line have been completed. | G40: LAS ANIMAS | I40: Above ground water gathering line froze and split next to the meter house. Approximately 1 bbl of produced water sprayed out on location and melted snow in the spray area. No water left location. | J40: The line has been repaired and the well is operating normally. | K40: Natural Force Damage | L40: Line Freeze | M40: -104.89455 | N40: 37.17172 | O40: 0 | Q40: 0 | S40: 1 | U40: 0 | W40: 0 | Y40: NULL | AA40: NULL | AC40: RATON BASIN | AD40: =IF(OR(IFERROR(SEARCH("gathering",F40)>0,FALSE),IFERROR(SEARCH("gathering",I40)>0,FALSE)),"Gathering","Non-Gathering") -> Gathering | AE40: Unknown | AF40: =VLOOKUP(A40,#REF!, 7, FALSE) -> #REF! | AG40: =VLOOKUP(A40,#REF!, 8, FALSE) -> #REF! | AI40: =VLOOKUP(A40,#REF!,40,FALSE) -> #REF!
...

Sheet Basin Blanks Report
A1: wkt_geom | B1: trkg_num | C1: ID | D1: NAME | E1: Lat | F1: Long
A2: Point (225301.88694792380556464 4418937.33076254185289145) | B2: 401066122 | C2: 5 | D2: PICEANCE BASIN | E2: 39.87603 | F2: -108.21202
A3: Point (212207.42134096095105633 4432217.81210820376873016) | B3: 400805034 | C3: 5 | D3: PICEANCE BASIN | E3: 39.99114 | F3: -108.37075
A4: Point (218351.65339279582258314 4420428.69138516299426556) | B4: 400928623 | C4: 5 | D4: PICEANCE BASIN | E4: 39.887167 | F4: -108.29381
A5: Point (221723.65403464291011915 4409716.03824181109666824) | B5: 400903075 | C5: 5 | D5: PICEANCE BASIN | E5: 39.791914 | F5: -108.24988
A6: Point (218744.71096766035770997 4418467.91733968257904053) | B6: 400988434 | C6: 5 | D6: PICEANCE BASIN | E6: 39.86966 | F6: -108.28837
A7: Point (221705.04365554690593854 4409626.33708230871707201) | B7: 401059925 | C7: 5 | D7: PICEANCE BASIN | E7: 39.791101 | F7: -108.25006
A8: Point (220964.69570344634121284 4538232.53896433860063553) | B8: 400844350 | C8: 11 | D8: SAND WASH BASIN | E8: 40.947591 | F8: -108.31495
A9: Point (524333.73634620720986277 4487656.81166545115411282) | B9: 400763258 | C9: 12 | D9: DENVER JULESBURG BASIN | E9: 40.539301 | F9: -104.71265
A10: Point (563740.76309913408476859 4479714.43669730983674526) | B10: 400764687 | C10: 12 | D10: DENVER JULESBURG BASIN | E10: 40.46566 | F10: -104.24814
A11: Point (726486.21336037595756352 4479458.49585274793207645) | B11: 400765386 | C11: 12 | D11: DENVER JULESBURG BASIN | E11: 40.43495 | F11: -102.32982
A12: Point (536128.02382295462302864 4458890.22588541265577078) | B12: 400771524 | C12: 12 | D12: DENVER JULESBURG BASIN | E12: 40.279715 | F12: -104.57502
A13: Point (719842.50813464284874499 4477981.58284935262054205) | B13: 400774763 | C13: 12 | D13: DENVER JULESBURG BASIN | E13: 40.42344 | F13: -102.40858
... A222: Point (537452.78215012652799487 4480230.48348690010607243) | B222: 401158551 | C222: 12 | D222: DENVER JULESBURG BASIN | E222: 40.47191 | F222: -104.55818
